I'm sorry, but an uncaught exception occurred.

While running game code:
  File "script.rpy", line 2614, in script
    watanabe "А, привет Кендзи! Гляди. Парень десять тысяч накрутил, а звёздочка распредвала — не съедена."
Exception: Sayer 'watanabe' is not defined.

-- Full Traceback ------------------------------------------------------------

Full traceback:
  File "script.rpy", line 2614, in script
    watanabe "А, привет Кендзи! Гляди. Парень десять тысяч накрутил, а звёздочка распредвала — не съедена."
  File "/home/daniel/Documents/Sources/renpy/renpy-7.3.2-sdk/renpy/ast.py", line 676, in execute
    who = eval_who(self.who, self.who_fast)
  File "/home/daniel/Documents/Sources/renpy/renpy-7.3.2-sdk/renpy/ast.py", line 574, in eval_who
    raise Exception("Sayer '%s' is not defined." % who.encode("utf-8"))
Exception: Sayer 'watanabe' is not defined.

Linux-4.19.0-8-amd64-x86_64-with-debian-10.3
Ren'Py 7.3.2.320
radiopulsarvn 1.0
Tue Mar  3 12:24:53 2020
